<?xml version="1.0" ?>
<sdf version="1.5">
  <model name="trash_can_35g">
    <self_collide>false</self_collide>
    <link name="base_link">
      <pose>0 0 0 0 0 0</pose>
      <inertial>
        <pose>0 0 0.4882 0 0 0</pose>
        <mass>55.5</mass>
        <inertia>
          <ixx>5.96</ixx>
          <ixy>0</ixy>
          <ixz>0</ixz>
          <iyy>7.02</iyy>
          <iyz>0</iyz>
          <izz>4.28</izz>
        </inertia>
      </inertial>

      <visual name="base_visual">
        <pose>0.1 0.13 0.13 0 0 0</pose>
        <geometry>
          <mesh>
            <uri>model://trash_can_35g/meshes/trash_can_body.dae</uri>
            <scale>0.28 0.28 0.28</scale>
          </mesh>
        </geometry>
      </visual>

      <collision name="back_base_collision">
        <pose>-0.12 0 0.15 0 0 0</pose>
        <geometry>
          <box>
            <!-- <size>0.48 0.6 0.9764</size> -->
            <size>0.24 0.3 0.28</size>
          </box>
        </geometry>
      </collision>

      <collision name="front_base_collision">
        <pose>0.12 0 0.15 0 0 0</pose>
        <geometry>
          <box>
            <size>0.24 0.55 0.28</size>
          </box>
        </geometry>
        <surface>
          <friction>
            <ode>
              <mu>1.0</mu>
              <mu2>1.0</mu2>
              <slip1>0.0</slip1>
              <slip2>0.0</slip2>
            </ode>
          </friction>
        </surface>
      </collision>

      <collision name="mid_base_collision">
        <pose>0 0 0.43 0 0 0</pose>
        <geometry>
          <box>
            <size>0.48 0.55 0.28</size>
          </box>
        </geometry>
      </collision>
      <collision name="top_base_collision">
        <pose>0 0 0.778 0 0 0</pose>
        <geometry>
          <box>
            <size>0.48 0.6 0.416</size>
          </box>
        </geometry>
      </collision>
    </link>

    <link name="left_wheel_link">
      <pose>-0.15 0.2 0.127 -1.57 0 0</pose>
      <inertial>
        <mass>2.72</mass>
        <inertia>
          <ixx>0.0118</ixx>
          <ixy>0</ixy>
          <ixz>0</ixz>
          <iyy>0.0118</iyy>
          <iyz>0</iyz>
          <izz>0.0037</izz>
        </inertia>
      </inertial>

      <visual name="left_wheel_visual">
        <geometry>
          <cylinder>
            <radius>0.127</radius>
            <length>0.06</length>
          </cylinder>
        </geometry>
        <material>
          <script>
            <name>Gazebo/Grey</name>
          </script>
        </material>
      </visual>

      <collision name="left_wheel_collision">
        <geometry>
          <cylinder>
            <radius>0.127</radius>
            <length>0.06</length>
          </cylinder>
        </geometry>
        <surface>
          <friction>
            <ode>
              <mu>1.0</mu>
              <mu2>0.0</mu2>
              <slip1>0</slip1>
              <slip2>0</slip2>
            </ode>
          </friction>
          <contact>
            <ode>
              <min_depth>0.005</min_depth>
              <kp>1e8</kp>
            </ode>
          </contact>
        </surface>
      </collision>
    </link>

    <link name="right_wheel_link">
      <pose>-0.15 -0.2 0.127 1.57 0 0</pose>
      <inertial>
        <mass>2.72</mass>
        <inertia>
          <ixx>0.0118</ixx>
          <ixy>0</ixy>
          <ixz>0</ixz>
          <iyy>0.0118</iyy>
          <iyz>0</iyz>
          <izz>0.0037</izz>
        </inertia>
      </inertial>

      <visual name="right_wheel_visual">
        <geometry>
          <cylinder>
            <radius>0.127</radius>
            <length>0.06</length>
          </cylinder>
        </geometry>
        <material>
          <script>
            <name>Gazebo/Grey</name>
          </script>
        </material>
      </visual>

      <collision name="right_wheel_collision">
        <geometry>
          <cylinder>
            <radius>0.127</radius>
            <length>0.06</length>
          </cylinder>
        </geometry>
        <surface>
          <friction>
            <ode>
              <mu>1.0</mu>
              <mu2>0.0</mu2>
              <slip1>0</slip1>
              <slip2>0</slip2>
            </ode>
          </friction>
          <contact>
            <ode>
              <min_depth>0.005</min_depth>
              <kp>1e8</kp>
            </ode>
          </contact>
        </surface>
      </collision>
    </link>
    <joint name="left_wheel_joint" type="revolute">
      <parent>base_link</parent>
      <child>left_wheel_link</child>
      <axis>
        <xyz>0 0 -1</xyz>
        <dynamics>
          <damping>.7</damping>
          <friction>.2</friction>
        </dynamics>
      </axis>
    </joint>
    <joint name="right_wheel_joint" type="revolute">
      <parent>base_link</parent>
      <child>right_wheel_link</child>
      <axis>
        <xyz>0 0 1</xyz>
        <dynamics>
          <damping>.7</damping>
          <friction>.2</friction>
        </dynamics>
      </axis>
    </joint>
  </model>
</sdf>
